<?xml version="1.0" encoding="UTF-8"?>
<robot name="cobotta" xmlns:xacro="http://www.ros.org/wiki/xacro">

        <xacro:macro name="cobotta_arm" params="arm_hw_interface:=PositionJointInterface">

	<link name="cobotta_base_link">
		<visual>
			<origin rpy="0 0 0" xyz="0 0 0"/>
			<geometry>
				<mesh filename="package://denso_cobotta_descriptions/cobotta_description/base_link.dae" scale="1 1 1"/>
			</geometry>
		</visual>
		<collision>
			<origin rpy="0 0 0" xyz="0 0 0"/>
			<geometry>
				<mesh filename="package://denso_cobotta_descriptions/cobotta_description/base_link.dae" scale="1 1 1"/>
			</geometry>
		</collision>
		<inertial>
			<mass value="4.3125"/>
			<origin rpy="0.000000 0.000000 0.000000" xyz="0.00056189 0.045262 -0.022289"/>
			<inertia ixx="1" ixy="0" ixz="0" iyy="1" iyz="0" izz="1"/>
		</inertial>
	</link>
	<link name="J1">
		<visual>
			<origin rpy="0 0 0" xyz="0 0 0"/>
			<geometry>
				<mesh filename="package://denso_cobotta_descriptions/cobotta_description/J1.dae" scale="1 1 1"/>
			</geometry>
		</visual>
		<collision>
			<origin rpy="0 0 0" xyz="0 0 0"/>
			<geometry>
				<mesh filename="package://denso_cobotta_descriptions/cobotta_description/J1.dae" scale="1 1 1"/>
			</geometry>
		</collision>
		<inertial>
			<mass value="0.70059"/>
			<origin rpy="0.000000 0.000000 0.000000" xyz="0.0066651 0.15765 -3.1112E-07"/>
			<inertia ixx="1" ixy="0" ixz="0" iyy="1" iyz="0" izz="1"/>
		</inertial>
	</link>
	<joint name="joint_1" type="revolute">
		<parent link="cobotta_base_link"/>
		<child link="J1"/>
		<origin rpy="0.000000 0.000000 0.000000" xyz="0.000000 0.000000 0.000000"/>
		<axis xyz="-0.000000 -0.000000 1.000000"/>
		<limit effort="1" lower="-2.617994" upper="2.617994" velocity="0.2"/>
		<dynamics damping="0" friction="0"/>
	</joint>
	<transmission name="trans_1">
		<type>transmission_interface/SimpleTransmission</type>
		<joint name="joint_1">
  			<hardwareInterface>${arm_hw_interface}</hardwareInterface>
		</joint>
		<actuator name="motor_1">
 			<hardwareInterface>${arm_hw_interface}</hardwareInterface>
			<mechanicalReduction>1</mechanicalReduction>
		</actuator>
	</transmission>
 
	<link name="J2">
		<visual>
			<origin rpy="0 0 0" xyz="0 0 0"/>
			<geometry>
				<mesh filename="package://denso_cobotta_descriptions/cobotta_description/J2.dae" scale="1 1 1"/>
			</geometry>
		</visual>
		<collision>
			<origin rpy="0 0 0" xyz="0 0 0"/>
			<geometry>
				<mesh filename="package://denso_cobotta_descriptions/cobotta_description/J2.dae" scale="1 1 1"/>
			</geometry>
		</collision>
		<inertial>
			<mass value="1.8946"/>
			<origin rpy="0.000000 0.000000 0.000000" xyz="0.089465 0.077303 -0.012737"/>
			<inertia ixx="1" ixy="0" ixz="0" iyy="1" iyz="0" izz="1"/>
		</inertial>
	</link>
	<joint name="joint_2" type="revolute">
		<parent link="J1"/>
		<child link="J2"/>
		<origin rpy="0.000000 0.000000 0.000000" xyz="0.000000 0.000000 0.180000"/>
		<axis xyz="-0.000000 1.000000 -0.000000"/>
		<limit effort="1" lower="-1.047198" upper="1.745329" velocity="0.2"/>
		<dynamics damping="0" friction="0"/>
	</joint>
	<transmission name="trans_2">
		<type>transmission_interface/SimpleTransmission</type>
		<joint name="joint_2">
			<hardwareInterface>${arm_hw_interface}</hardwareInterface>
		</joint>
		<actuator name="motor_2">
			<hardwareInterface>${arm_hw_interface}</hardwareInterface>
			<mechanicalReduction>1</mechanicalReduction>
		</actuator>
	</transmission>

	<link name="J3">
		<visual>
			<origin rpy="0 0 0" xyz="0 0 0"/>
			<geometry>
				<mesh filename="package://denso_cobotta_descriptions/cobotta_description/J3.dae" scale="1 1 1"/>
			</geometry>
		</visual>
		<collision>
			<origin rpy="0 0 0" xyz="0 0 0"/>
			<geometry>
				<mesh filename="package://denso_cobotta_descriptions/cobotta_description/J3.dae" scale="1 1 1"/>
			</geometry>
		</collision>
		<inertial>
			<mass value="1.1026"/>
			<origin rpy="0.000000 0.000000 0.000000" xyz="0.023381 0.026743 -0.0052682"/>
			<inertia ixx="1" ixy="0" ixz="0" iyy="1" iyz="0" izz="1"/>
		</inertial>
	</link>
	<joint name="joint_3" type="revolute">
		<parent link="J2"/>
		<child link="J3"/>
		<origin rpy="0.000000 0.000000 0.000000" xyz="0.000000 0.000000 0.165000"/>
		<axis xyz="-0.000000 1.000000 -0.000000"/>
		<limit effort="1" lower="0.3141593" upper="2.443461" velocity="0.2"/>
		<dynamics damping="0" friction="0"/>
	</joint>
	<transmission name="trans_3">
		<type>transmission_interface/SimpleTransmission</type>
		<joint name="joint_3">
			<hardwareInterface>${arm_hw_interface}</hardwareInterface>
		</joint>
		<actuator name="motor_3">
			<hardwareInterface>${arm_hw_interface}</hardwareInterface>
			<mechanicalReduction>1</mechanicalReduction>
		</actuator>
	</transmission>

	<link name="J4">
		<visual>
			<origin rpy="0 0 0" xyz="0 0 -0.522500"/>
			<geometry>
				<mesh filename="package://denso_cobotta_descriptions/cobotta_description/J4.dae" scale="1 1 1"/>
			</geometry>
		</visual>
		<collision>
			<origin rpy="0 0 0" xyz="0 0 0"/>
			<geometry>
				<mesh filename="package://denso_cobotta_descriptions/cobotta_description/J4.dae" scale="1 1 1"/>
			</geometry>
		</collision>
		<inertial>
			<mass value="0.81632"/>
			<origin rpy="0.000000 0.000000 0.000000" xyz="0.018578 0.14195 -0.011998"/>
			<inertia ixx="1" ixy="0" ixz="0" iyy="1" iyz="0" izz="1"/>
		</inertial>
	</link>
	<joint name="joint_4" type="revolute">
		<parent link="J3"/>
		<child link="J4"/>
		<origin rpy="0.000000 0.000000 0.000000" xyz="-0.012000 0.020000 0.1775"/>
		<axis xyz="-0.000000 -0.000000 1.000000"/>
		<limit effort="1" lower="-2.96706" upper="2.96706" velocity="0.2"/>
		<dynamics damping="0" friction="0"/>
	</joint>
	<transmission name="trans_4">
		<type>transmission_interface/SimpleTransmission</type>
		<joint name="joint_4">
			<hardwareInterface>${arm_hw_interface}</hardwareInterface>
		</joint>
		<actuator name="motor_4">
			<hardwareInterface>${arm_hw_interface}</hardwareInterface>
			<mechanicalReduction>1</mechanicalReduction>
		</actuator>
	</transmission>
	<link name="J5">
		<visual>
			<origin rpy="0 0 0" xyz="0 0 0"/>
			<geometry>
				<mesh filename="package://denso_cobotta_descriptions/cobotta_description/J5.dae" scale="1 1 1"/>
			</geometry>
		</visual>
		<collision>
			<origin rpy="0 0 0" xyz="0 0 0"/>
			<geometry>
				<mesh filename="package://denso_cobotta_descriptions/cobotta_description/J5.dae" scale="1 1 1"/>
			</geometry>
		</collision>
		<inertial>
			<mass value="0.46625"/>
			<origin rpy="0.000000 0.000000 0.000000" xyz="0.0044081 2.4993E-07 0.0077893"/>
			<inertia ixx="1" ixy="0" ixz="0" iyy="1" iyz="0" izz="1"/>
		</inertial>
	</link>
	<joint name="joint_5" type="revolute">
		<parent link="J4"/>
		<child link="J5"/>
		<origin rpy="0.000000 0.000000 0.000000" xyz="0.000000 -0.020000 0.000000"/>
		<axis xyz="-0.000000 1.000000 -0.000000"/>
		<limit effort="1" lower="-1.658063" upper="2.356194" velocity="0.2"/>
		<dynamics damping="0" friction="0"/>
	</joint>
	<transmission name="trans_5">
		<type>transmission_interface/SimpleTransmission</type>
		<joint name="joint_5">
			<hardwareInterface>${arm_hw_interface}</hardwareInterface>
		</joint>
		<actuator name="motor_5">
			<hardwareInterface>${arm_hw_interface}</hardwareInterface>
			<mechanicalReduction>1</mechanicalReduction>
		</actuator>
	</transmission>
	<link name="J6">
		<visual>
			<origin rpy="0 0 0" xyz="0 0 0"/>
			<geometry>
				<mesh filename="package://denso_cobotta_descriptions/cobotta_description/J6.dae" scale="1 1 1"/>
			</geometry>
		</visual>
		<collision>
			<origin rpy="0 0 0" xyz="0 0 0"/>
			<geometry>
				<mesh filename="package://denso_cobotta_descriptions/cobotta_description/J6.dae" scale="1 1 1"/>
			</geometry>
		</collision>
		<inertial>
			<mass value="0.03"/>
			<origin rpy="0.000000 0.000000 0.000000" xyz="0.000000 0.000000 0.000000"/>
			<inertia ixx="1" ixy="0" ixz="0" iyy="1" iyz="0" izz="1"/>
		</inertial>
	</link>
	<joint name="joint_6" type="revolute">
		<parent link="J5"/>
		<child link="J6"/>
		<origin rpy="0.000000 0.000000 0.000000" xyz="0.000000 -0.044500 0.042000"/>
		<axis xyz="-0.000000 -0.000000 1.000000"/>
		<limit effort="1" lower="-2.96706" upper="2.96706" velocity="0.2"/>
		<dynamics damping="0" friction="0"/>
	</joint>
	<transmission name="trans_6">
		<type>transmission_interface/SimpleTransmission</type>
		<joint name="joint_6">
			<hardwareInterface>${arm_hw_interface}</hardwareInterface>
		</joint>
		<actuator name="motor_6">
			<hardwareInterface>${arm_hw_interface}</hardwareInterface>
			<mechanicalReduction>1</mechanicalReduction>
		</actuator>
        </transmission>
        
	<link name="gripper_base">
		<visual>
			<origin rpy="0 0 0" xyz="0.000000 0.000000 0.000000"/>
			<geometry>
				<mesh filename="package://denso_cobotta_descriptions/cobotta_description/gripper_base.dae" scale="1 1 1"/>
			</geometry>
		</visual>
		<collision>
			<origin rpy="0 0 0" xyz="0 0 0"/>
			<geometry>
				<mesh filename="package://denso_cobotta_descriptions/cobotta_description/gripper_base.dae" scale="1 1 1"/>
			</geometry>
		</collision>
		<inertial>
			<mass value="0.05"/>
			<origin rpy="0.000000 0.000000 0.000000" xyz="0.000000 0.000000 0.023089"/>
			<inertia ixx="1" ixy="0" ixz="0" iyy="1" iyz="0" izz="1"/>
		</inertial>
	</link>
	<joint name="joint_gripper_base" type="fixed">
		<parent link="J6"/>
		<child link="gripper_base"/>
		<origin rpy="0.000000 0.000000 0.000000" xyz="0.000000 0.000000 0.0000000"/>
	</joint>
	<link name="left_finger">
		<visual>
			<origin rpy="0.000000 0.000000 0.000000" xyz="0.000000 0.000000 -0.060000"/>
			<geometry>
				<mesh filename="package://denso_cobotta_descriptions/cobotta_description/left_finger.dae" scale="1 1 1"/>
			</geometry>
		</visual>
		<collision>
			<origin rpy="0 0 0" xyz="0.000000 0.000000 -0.060000"/>
			<geometry>
				<mesh filename="package://denso_cobotta_descriptions/cobotta_description/left_finger.dae" scale="1 1 1"/>
			</geometry>
		</collision>
		<inertial>
			<mass value="0.01"/>
			<origin rpy="0.000000 0.000000 0.000000" xyz="0.000000 0.000000 0.000000"/>
			<inertia ixx="1" ixy="0" ixz="0" iyy="1" iyz="0" izz="1"/>
		</inertial>
	</link>
	<joint name="joint_gripper" type="prismatic">
		<parent link="gripper_base"/>
		<child link="left_finger"/>
		<origin rpy="0.000000 0.000000 0.000000" xyz="0.000000 0.000000 0.06000"/>
		<axis xyz="-0.000000 1.000000 -0.000000"/>
		<limit effort="1" lower="0.000000" upper="0.015000" velocity="0.040000"/>
		<dynamics damping="0" friction="0"/>
	</joint>
	<transmission name="trans_gripper">
		<type>transmission_interface/SimpleTransmission</type>
		<joint name="joint_gripper">
			<hardwareInterface>${arm_hw_interface}</hardwareInterface>
		</joint>
		<actuator name="motor_gripper">
			<hardwareInterface>${arm_hw_interface}</hardwareInterface>
			<mechanicalReduction>1</mechanicalReduction>
		</actuator>
	</transmission>
	<link name="right_finger">
		<visual>
			<origin rpy="0.000000 0.000000 0.000000" xyz="0.000000 0.000000 -0.060000"/>
			<geometry>
				<mesh filename="package://denso_cobotta_descriptions/cobotta_description/right_finger.dae" scale="1 1 1"/>
			</geometry>
		</visual>
		<collision>
			<origin rpy="0 0 0" xyz="0.000000 0.000000 -0.060000"/>
			<geometry>
				<mesh filename="package://denso_cobotta_descriptions/cobotta_description/right_finger.dae" scale="1 1 1"/>
			</geometry>
		</collision>
		<inertial>
			<mass value="0.01"/>
			<origin rpy="0.000000 0.000000 0.000000" xyz="0.000000 0.000000 0.000000"/>
			<inertia ixx="1" ixy="0" ixz="0" iyy="1" iyz="0" izz="1"/>
		</inertial>
	</link>
	<joint name="joint_gripper_mimic" type="prismatic">
		<parent link="gripper_base"/>
		<child link="right_finger"/>
		<mimic joint="joint_gripper" multiplier="-1.000000" offset="0.000000"/>
		<origin rpy="0.000000 0.000000 0.000000" xyz="0.000000 0.000000 0.060000"/>
		<axis xyz="-0.000000 1.000000 -0.000000"/>
		<limit effort="1" lower="-0.015000" upper="0.000000" velocity="0.040000"/>
		<dynamics damping="0" friction="0"/>
	</joint>

        </xacro:macro> 
        
</robot>
